<?xml version="1.0" encoding="UTF-8"?>
<!-- Generated by org.testng.reporters.JUnitReportReporter -->
<testsuite skipped="0" hostname="Chan" name="com.crm.SDET26.opportunity.CreateOpportunitywithSalesStageClosedLostTest" tests="1" failures="1" timestamp="16 Dec 2021 17:10:22 GMT" time="74.106" errors="0">
  <testcase name="createOpportunitywithSalesStageClosedLost" time="74.106" classname="com.crm.SDET26.opportunity.CreateOpportunitywithSalesStageClosedLostTest">
    <failure type="java.lang.AssertionError" message="The following asserts failed:
	expected [Team Selling] but found [Team Selling  ]">
      <![CDATA[java.lang.AssertionError: The following asserts failed:
expected [Team Selling] but found [Team Selling  ]
at org.testng.asserts.SoftAssert.assertAll(SoftAssert.java:43)
at com.crm.SDET26.opportunity.CreateOpportunitywithSalesStageClosedLostTest.createOpportunitywithSalesStageClosedLost(CreateOpportunitywithSalesStageClosedLostTest.java:69)
at sun.reflect.NativeMethodAccessorImpl.invoke0(Native Method)
at sun.reflect.NativeMethodAccessorImpl.invoke(Unknown Source)
at sun.reflect.DelegatingMethodAccessorImpl.invoke(Unknown Source)
at java.lang.reflect.Method.invoke(Unknown Source)
at org.testng.internal.MethodInvocationHelper.invokeMethod(MethodInvocationHelper.java:124)
at org.testng.internal.Invoker.invokeMethod(Invoker.java:583)
at org.testng.internal.Invoker.invokeTestMethod(Invoker.java:719)
at org.testng.internal.Invoker.invokeTestMethods(Invoker.java:989)
at org.testng.internal.TestMethodWorker.invokeTestMethods(TestMethodWorker.java:125)
at org.testng.internal.TestMethodWorker.run(TestMethodWorker.java:109)
at java.util.concurrent.ThreadPoolExecutor.runWorker(Unknown Source)
at java.util.concurrent.ThreadPoolExecutor$Worker.run(Unknown Source)
at java.lang.Thread.run(Unknown Source)
]]>
    </failure>
  </testcase> <!-- createOpportunitywithSalesStageClosedLost -->
</testsuite> <!-- com.crm.SDET26.opportunity.CreateOpportunitywithSalesStageClosedLostTest -->
